2025-01-23 11:42:07,024 - INFO - Inicio del proceso de sincronización...
2025-01-23 11:42:07,771 - ERROR - Error durante la sincronización: Failed raising error.
Traceback (most recent call last):
  File "main.py", line 15, in <module>
  File "sincronizador.py", line 118, in sincronizarTodo
  File "dbTest.py", line 13, in establecerConexion
  File "mysql\connector\pooling.py", line 322, in connect
  File "mysql\connector\connection_cext.py", line 151, in __init__
  File "mysql\connector\abstracts.py", line 1426, in connect
  File "mysql\connector\connection_cext.py", line 335, in _open_connection
RuntimeError: Failed raising error.
2025-01-23 11:42:07,773 - INFO - Fin del proceso.
